Traceback (most recent call last):
  File "/Users/lilshoe/miniconda3/envs/mldl/lib/python3.11/site-packages/sqlalchemy/engine/base.py", line 1963, in _exec_single_context
    self.dialect.do_execute(
  File "/Users/lilshoe/miniconda3/envs/mldl/lib/python3.11/site-packages/sqlalchemy/engine/default.py", line 943, in do_execute
    cursor.execute(statement, parameters)
sqlite3.IntegrityError: UNIQUE constraint failed: studies.study_name

The above exception was the direct cause of the following exception:

Traceback (most recent call last):
  File "/Users/lilshoe/miniconda3/envs/mldl/lib/python3.11/site-packages/optuna/storages/_rdb/storage.py", line 273, in create_new_study
    with _create_scoped_session(self.scoped_session) as session:
  File "/Users/lilshoe/miniconda3/envs/mldl/lib/python3.11/contextlib.py", line 144, in __exit__
    next(self.gen)
  File "/Users/lilshoe/miniconda3/envs/mldl/lib/python3.11/site-packages/optuna/storages/_rdb/storage.py", line 78, in _create_scoped_session
    session.commit()
  File "/Users/lilshoe/miniconda3/envs/mldl/lib/python3.11/site-packages/sqlalchemy/orm/session.py", line 2032, in commit
    trans.commit(_to_root=True)
  File "<string>", line 2, in commit
  File "/Users/lilshoe/miniconda3/envs/mldl/lib/python3.11/site-packages/sqlalchemy/orm/state_changes.py", line 139, in _go
    ret_value = fn(self, *arg, **kw)
                ^^^^^^^^^^^^^^^^^^^^
  File "/Users/lilshoe/miniconda3/envs/mldl/lib/python3.11/site-packages/sqlalchemy/orm/session.py", line 1313, in commit
    self._prepare_impl()
  File "<string>", line 2, in _prepare_impl
  File "/Users/lilshoe/miniconda3/envs/mldl/lib/python3.11/site-packages/sqlalchemy/orm/state_changes.py", line 139, in _go
    ret_value = fn(self, *arg, **kw)
                ^^^^^^^^^^^^^^^^^^^^
  File "/Users/lilshoe/miniconda3/envs/mldl/lib/python3.11/site-packages/sqlalchemy/orm/session.py", line 1288, in _prepare_impl
    self.session.flush()
  File "/Users/lilshoe/miniconda3/envs/mldl/lib/python3.11/site-packages/sqlalchemy/orm/session.py", line 4345, in flush
    self._flush(objects)
  File "/Users/lilshoe/miniconda3/envs/mldl/lib/python3.11/site-packages/sqlalchemy/orm/session.py", line 4480, in _flush
    with util.safe_reraise():
  File "/Users/lilshoe/miniconda3/envs/mldl/lib/python3.11/site-packages/sqlalchemy/util/langhelpers.py", line 224, in __exit__
    raise exc_value.with_traceback(exc_tb)
  File "/Users/lilshoe/miniconda3/envs/mldl/lib/python3.11/site-packages/sqlalchemy/orm/session.py", line 4441, in _flush
    flush_context.execute()
  File "/Users/lilshoe/miniconda3/envs/mldl/lib/python3.11/site-packages/sqlalchemy/orm/unitofwork.py", line 466, in execute
    rec.execute(self)
  File "/Users/lilshoe/miniconda3/envs/mldl/lib/python3.11/site-packages/sqlalchemy/orm/unitofwork.py", line 642, in execute
    util.preloaded.orm_persistence.save_obj(
  File "/Users/lilshoe/miniconda3/envs/mldl/lib/python3.11/site-packages/sqlalchemy/orm/persistence.py", line 93, in save_obj
    _emit_insert_statements(
  File "/Users/lilshoe/miniconda3/envs/mldl/lib/python3.11/site-packages/sqlalchemy/orm/persistence.py", line 1233, in _emit_insert_statements
    result = connection.execute(
             ^^^^^^^^^^^^^^^^^^^
  File "/Users/lilshoe/miniconda3/envs/mldl/lib/python3.11/site-packages/sqlalchemy/engine/base.py", line 1415, in execute
    return meth(
           ^^^^^
  File "/Users/lilshoe/miniconda3/envs/mldl/lib/python3.11/site-packages/sqlalchemy/sql/elements.py", line 523, in _execute_on_connection
    return connection._execute_clauseelement(
           ^^^^^^^^^^^^^^^^^^^^^^^^^^^^^^^^^^
  File "/Users/lilshoe/miniconda3/envs/mldl/lib/python3.11/site-packages/sqlalchemy/engine/base.py", line 1637, in _execute_clauseelement
    ret = self._execute_context(
          ^^^^^^^^^^^^^^^^^^^^^^
  File "/Users/lilshoe/miniconda3/envs/mldl/lib/python3.11/site-packages/sqlalchemy/engine/base.py", line 1842, in _execute_context
    return self._exec_single_context(
           ^^^^^^^^^^^^^^^^^^^^^^^^^^
  File "/Users/lilshoe/miniconda3/envs/mldl/lib/python3.11/site-packages/sqlalchemy/engine/base.py", line 1982, in _exec_single_context
    self._handle_dbapi_exception(
  File "/Users/lilshoe/miniconda3/envs/mldl/lib/python3.11/site-packages/sqlalchemy/engine/base.py", line 2351, in _handle_dbapi_exception
    raise sqlalchemy_exception.with_traceback(exc_info[2]) from e
  File "/Users/lilshoe/miniconda3/envs/mldl/lib/python3.11/site-packages/sqlalchemy/engine/base.py", line 1963, in _exec_single_context
    self.dialect.do_execute(
  File "/Users/lilshoe/miniconda3/envs/mldl/lib/python3.11/site-packages/sqlalchemy/engine/default.py", line 943, in do_execute
    cursor.execute(statement, parameters)
sqlalchemy.exc.IntegrityError: (sqlite3.IntegrityError) UNIQUE constraint failed: studies.study_name
[SQL: INSERT INTO studies (study_name) VALUES (?)]
[parameters: ('maddpg_balance_tuning_wandb102',)]
(Background on this error at: https://sqlalche.me/e/20/gkpj)

During handling of the above exception, another exception occurred:

Traceback (most recent call last):
  File "/Users/lilshoe/Library/Mobile Documents/com~apple~CloudDocs/Politecnico Torino/Anno 2024-2025/Secondo Semestre/Machine Learning and Deep Learning/Progetto /Project_Codes/MADDPG copia/tuning.py", line 139, in <module>
    study = optuna.create_study(
            ^^^^^^^^^^^^^^^^^^^^
  File "/Users/lilshoe/miniconda3/envs/mldl/lib/python3.11/site-packages/optuna/_convert_positional_args.py", line 135, in converter_wrapper
    return func(**kwargs)  # type: ignore[call-arg]
           ^^^^^^^^^^^^^^
  File "/Users/lilshoe/miniconda3/envs/mldl/lib/python3.11/site-packages/optuna/study/study.py", line 1297, in create_study
    study_id = storage.create_new_study(direction_objects, study_name)
               ^^^^^^^^^^^^^^^^^^^^^^^^^^^^^^^^^^^^^^^^^^^^^^^^^^^^^^^
  File "/Users/lilshoe/miniconda3/envs/mldl/lib/python3.11/site-packages/optuna/storages/_cached_storage.py", line 78, in create_new_study
    study_id = self._backend.create_new_study(directions=directions, study_name=study_name)
               ^^^^^^^^^^^^^^^^^^^^^^^^^^^^^^^^^^^^^^^^^^^^^^^^^^^^^^^^^^^^^^^^^^^^^^^^^^^^
  File "/Users/lilshoe/miniconda3/envs/mldl/lib/python3.11/site-packages/optuna/storages/_rdb/storage.py", line 285, in create_new_study
    raise optuna.exceptions.DuplicatedStudyError(
optuna.exceptions.DuplicatedStudyError: Another study with name 'maddpg_balance_tuning_wandb102' already exists. Please specify a different name, or reuse the existing one by setting `load_if_exists` (for Python API) or `--skip-if-exists` flag (for CLI).
